Workbook
Name IQ_CH: 110000
Name IQ_CQ: 5000
Name IQ_CY: 10000
Name IQ_DAILY: 500000
Name IQ_FH: 100000
Name IQ_FQ: 500
Name IQ_FY: 1000
Name IQ_LTM: 2000
Name IQ_MONTH: 15000
Name IQ_NTM: 6000
Name IQ_WEEK: 50000
Name IQ_YTD: 3000

Sheet cover
B2: #VALUE!
B3: One of the cheapest gene therapies in history with solid value proposition
B5: Price | C5: {=_FV(B2,"Price")} -> 5.07 | E5: risk adjusted net present value
B6: Shares | C6: 52.4 | F6: ='risk adjusted post approval '!F104 -> Equity Value | H6: ='risk adjusted post approval '!G104 -> per share
B7: MC | C7: =C5*C6 -> 265.668 | E7: ='risk adjusted post approval '!E105 -> r= 7.61% | F7: ='risk adjusted post approval '!F105 -> 840.02572 | H7: ='risk adjusted post approval '!G105 -> 17.320118
B8: Cash & ST | C8: 207.1 | E8: ='risk adjusted post approval '!E106 -> r= 15% | F8: ='risk adjusted post approval '!F106 -> 640.30378 | H8: ='risk adjusted post approval '!G106 -> 13.20214
B9: Debt | C9: 24.1 | E9: ='risk adjusted post approval '!E107 -> r= 20% | F9: ='risk adjusted post approval '!F107 -> 552.00831 | H9: ='risk adjusted post approval '!G107 -> 11.381615
B10: EV | C10: =C7+C9-C8 -> 82.668
E11: ='risk adjusted post approval '!E109 -> Risk adjusted | F11: ='risk adjusted post approval '!F109 -> Equity value | H11: ='risk adjusted post approval '!G109 -> per share
B12: model estimates… | E12: ='risk adjusted post approval '!E110 -> r= 7.61% | F12: ='risk adjusted post approval '!F110 -> 558.95352 | H12: ='risk adjusted post approval '!G110 -> 11.524815
B13: Peak Sales | C13: 688 | D13: =C10/C13 -> 0.12015698 | E13: ='risk adjusted post approval '!E111 -> r= 15% | F13: ='risk adjusted post approval '!F111 -> 442.74332 | H13: ='risk adjusted post approval '!G111 -> 9.1287282
B14: 3Y Fwd Sales | C14: 290 | D14: =C10/C14 -> 0.28506207 | E14: ='risk adjusted post approval '!E112 -> r= 20% | F14: ='risk adjusted post approval '!F112 -> 391.53054 | H14: ='risk adjusted post approval '!G112 -> 8.0727947
B15: Cumulative 10Y | C15: =SUM('risk adjusted post approval '!F39:P39) -> 1920.0372
B16: EV/ c. 10y | C16: =C10/C15 -> 0.043055416
B18: Catalyst | C18: FY 2025
B20: EV @ 0.15x c.10y | C20: =C15*0.15 -> 288.00558
B21: Cash | C21: =C8 -> 207.1
B22: Debt | C22: =C9 -> 24.1
B23: FV | C23: =C20+C21-C22 -> 471.00558
C24: =C23/C6 -> 8.9886561
B26: Developer | C26: Owner | D26: Therapy | E26: Market | F26: Patients | G26: Price | H26: Opportunity $B | I26: Peak Sales | J26: MC/EV | K26: Peak Sales Multiple | L26: Opportunity Multiple | M26: Notes
A27: acq. | B27: AveXis | C27: Novartis | D27: Zolgensma | E27: spinal muscular atrophy | F27: 10000 | G27: 2100000 | H27: =F27*G27/1000000000 -> 21 | I27: 1300 | J27: 8700 | K27: =J27/I27 -> 6.6923077 | L27: =J27/1000/H27 -> 0.41428571
A28: acq. | B28: BioVex | C28: Amgen | D28: Imlygic | E28: melanoma | H28: =F28*G28/1000000000 -> 0 | I28: 200 | J28: 1000 | K28: =J28/I28 -> 5 | M28: (Bad comparison, ignore ) This was acquired in 2011 for up to $1B (including milestones, which were achieved) with peak sales potential of $200. Approval in 2015. Did not reach peak sales (realised 100-150M)
A29: > | B29: Krystal | C29: Krystal | D29: Vyjuvek | E29: DEB | F29: 4000 | G29: 600000 | H29: =F29*G29/1000000000 -> 2.4 | I29: 900 | J29: 4000 | K29: =J29/I29 -> 4.4444444 | L29: =J29/1000/H29 -> 1.6666667
A30: acq. | B30: Spark Tx | C30: Spark Tx (Roche) | D30: Luxturna | E30: Leber congenital amaurosis | F30: 3000 | G30: 850000 | H30: =F30*G30/1000000000 -> 2.55 | I30: 750 | J30: 4300 | K30: =J30/I30 -> 5.7333333 | L30: =J30/1000/H30 -> 1.6862745 | M30: Bought for $4.3B in 2019. Had estimated peak sales of $350-750, lifetime opportunity of $1-3B. Never realised this, was a miserable failure
A31: > | B31: UCL | C31: Autolus | D31: Aucatzyl | E31: ALL | F31: 1000 | G31: 525000 | H31: =F31*G31/1000000000 -> 0.525 | I31: 300 | J31: 322 | K31: =J31/I31 -> 1.0733333 | L31: =J31/1000/H31 -> 0.61333333 | M31: Note: I met the CEO at UBS. 6100 ALL diagnoses. 50% adults --> 3000. 75% B-cell precursor --> 2250. r/r 50% --> 1100 patients per year. --> $500M in peak sales. WB estimates $300 (public)
A32: > | B32: SRPT | C32: SRPT | D32: Elevidys | E32: DMD | F32: 6000 | G32: 3200000 | H32: =F32*G32/1000000000 -> 19.2 | I32: 2500 | J32: 2000 | K32: =J32/I32 -> 0.8 | L32: =J32/1000/H32 -> 0.10416667 | M32: Even after all the problems and associated risks, we are trading at more than 2x the Abeona multple. Also, we have been very generous with SRPT revenue forecast
A33: acq | B33: BMS & 2seventy | C33: BMS | D33: Abecma | E33: Multiple myeloma | F33: 127000 | G33: =419500 -> 419500 | H33: =F33*G33/1000000000 -> 53.2765 | I33: 224 | J33: =4.75*57.1-184 -> 87.225 | K33: =J33/I33 -> 0.38939732 | L33: =J33/1000/H33 -> 0.0016372134 | M33: (CAR-T) Peak sales estimate of $224M (2029) is from financial advisor (GS) during acquisition for valuation for $4.75 per share, 57.1M shares, Cash & ST of $184 at the time of acq.
B34: Abeona | C34: Abeona | D34: Zevaskyn | E34: RDEB | F34: 765 | G34: 3200000 | H34: =F34*G34/1000000000 -> 2.448 | I34: 688 | J34: =$C$10 -> 82.668 | K34: =J34/I34 -> 0.12015698 | L34: =J34/1000/H34 -> 0.033769608 | M34: risk adjusted post approval '!A1
A35: x | B35: Ferring | C35: Ferring | D35: Adstiladrin | E35: bladder cancer | F35: 15000 | G35: 240000 | H35: =F35*G35/1000000000 -> 3.6 | I35: 1400
A36: x | B36: uniQure | C36: uniQure | D36: Glybera | E36: LPD | K36: Median | L36: =MEDIAN(L27:L34) -> 0.41428571
A37: x | B37: Kite Pharma | C37: Gilead | D37: Yescarta | E37: B cell lymphoma
A38: x | B38: bluebird bio | C38: bluebird bio | D38: Zynteglo | E38: Beta thalassemia
A39: x | B39: Kite Pharma | C39: Gilead | D39: Tecartus | E39: Mantle cell lymphoma + ALL
A40: x | B40: Human Stem cell institute | D40: Neovasculgen | E40: Peripheral artery disease
A41: x | B41: JNJ | C41: JNJ | D41: Carvykti | E41: Multiple myeloma
A42: x | B42: bluebird bio | C42: bluebird bio | D42: Skysona | E42: adrenoleukodystorphy
A43: x | B43: uniQure | C43: CSL Behring | D43: Hemgenix | E43: hemophilia B
B44: Vertex & CRISPR | C44: Vertex & CRISPR | D44: Casgevy | E44: sickle cell
A45: x | B45: bluebird bio | C45: bluebird bio | D45: Lyfgenia | E45: sickle cell
...

Sheet model 
A1: Research
B3: RDEB All | C3: Prevalence / mn | D3: Incidence /mn | E3: US pop mn | F3: Patient pop | G3: Notes
B4: Eichstadt et al (2019) | C4: =12562/340 -> 36.947059 | D4: 95 | E4: 340 | F4: =C4*E4 -> 12562 | G4: Unreliable genetic model
B5: Prop. Claims analysis (Abeona) | C5: =750/E5 -> 2.2058824 | D5: NA | E5: 340 | F5: 750 | G5: Method unavailable
A6: > | B6: Fine et al | C6: 1.35 | D6: 3.05 | E6: 340 | F6: =C6*E6 -> 459 | G6: NEBR data, most commonly cited
A7: > | B7: Baardman et al | C7: 2.1 | D7: 5.5 | E7: 340 | F7: =E7*C7 -> 714 | G7: Dutch EB registry
B8: Kim et al | E8: 340
A9: > | B9: Petrof et al | C9: 3.3 | D9: 8.1 | E9: 340 | F9: =C9*E9 -> 1122 | G9: NHS England and Wales
B10: Average | C10: =AVERAGE(C6:C9) -> 2.25 | D10: =AVERAGE(D6:D9) -> 5.55 | F10: =AVERAGE(F6:F9) -> 765
B12: RDEB patient "churn rate" | C12: =(D10*3.6)/F10 -> 0.026117647
B13: Implied life expectancy | C13: =1/C12 -> 38.288288
B14: Assuming 3.6 million live births
I15: (approval)
B16: Competition | C16: Vyjuvek | E16: #VALUE! | H16: KRYS uptake | I16: Q2 2023 | J16: Q3 2023 | K16: Q4 2023 | L16: Q1 2024 | M16: Q2 2024 | N16: Q3 2024 | O16: Q4 2024
B17: Marketing auth holder | C17: KRYS | E17: MC | F17: {=_FV(E16,"Market cap",TRUE)/1000000} -> 8083.6386 | G17: M | H17: Revenue | J17: 8.6 | K17: 42.1 | L17: 45.3 | M17: 70.3 | N17: 83.8 | O17: 91.1
B18: annualised sales (ASP) | C18: =91.1 * 4 -> 364.4 | E18: Cash | F18: 724.76 | G18: bpc 11.09.25 | H18: Patients treated | J18: =J17*1000000/($F$21/4) -> 68.690967 | K18: =K17*1000000/($F$21/4) -> 336.26624 | L18: =L17*1000000/($F$21/4) -> 361.82567 | M18: =M17*1000000/($F$21/4) -> 561.50872 | N18: =N17*1000000/($F$21/4) -> 669.33756 | O18: =O17*1000000/($F$21/4) -> 727.64501
B19: Sales (retail) | C19: =C18*1.26 -> 459.144 | E19: EV | F19: =F17-F18 -> 7358.8786 | G19: M | H19: patient pop | J19: =$C$23 -> 1108.4 | K19: =$C$23 -> 1108.4 | L19: =$C$23 -> 1108.4 | M19: =$C$23 -> 1108.4 | N19: =$C$23 -> 1108.4 | O19: =$C$23 -> 1108.4
B20: Pricing (list) - patient year | C20: 631000 | E20: Peak sales | F20: =F21*F22/1000000 -> 1001.5873 | G20: M | H20: % of peak | J20: =J18/J19 -> 0.061973084 | K20: =K18/K19 -> 0.30337987 | L20: =L18/L19 -> 0.32643962 | M20: =M18/M19 -> 0.50659393 | N20: =N18/N19 -> 0.60387726 | O20: =O18/O19 -> 0.65648232
B21: Patients | C21: =C19*1000000/C20 -> 727.64501 | E21: ASP/patient y | F21: =C18*1000000/C21 -> 500793.65 | G21: $ | O21: quick uptake
B22: Peak patients | C22: 2000 | D22: RDEB + DDEB | E22: Peak patients | F22: =C22 -> 2000
A23: ??? | B23: DEB prevalence (JD Fine) | C23: =340*3.26 -> 1108.4 | E23: EV-Peak sales | F23: =F19/F20 -> 7.3472164 | G23: x
B24: RDEB | C24: 765
A26: Model
C27: Notes | D27: 2022 | E27: 2023 | F27: 2024 | Q27: check patent expiry date ...
B28: US population | G28: 2025 | H28: =G28+1 -> 2026 | I28: =H28+1 -> 2027 | J28: =I28+1 -> 2028 | K28: =J28+1 -> 2029 | L28: =K28+1 -> 2030 | M28: =L28+1 -> 2031 | N28: =M28+1 -> 2032 | O28: =N28+1 -> 2033 | ... X28: =W28+1 -> 2042
B29: Prevalence | C29: [1] | G29: 340 | H29: 340 | I29: 340 | J29: 340 | K29: 340 | L29: 340 | M29: 340 | N29: 340 | O29: 340 | P29: 340 | Q29: 340 | R29: 340 | S29: 340 | T29: 340 | U29: 340 | V29: 340 | W29: 340 | X29: 340
B30: Patient population | G30: =AVERAGE($C$9,$C$7,$C$6) -> 2.25 | H30: =AVERAGE($C$9,$C$7,$C$6) -> 2.25 | I30: =AVERAGE($C$9,$C$7,$C$6) -> 2.25 | J30: =AVERAGE($C$9,$C$7,$C$6) -> 2.25 | K30: =AVERAGE($C$9,$C$7,$C$6) -> 2.25 | L30: =AVERAGE($C$9,$C$7,$C$6) -> 2.25 | M30: =AVERAGE($C$9,$C$7,$C$6) -> 2.25 | N30: =AVERAGE($C$9,$C$7,$C$6) -> 2.25 | ... X30: =AVERAGE($C$9,$C$7,$C$6) -> 2.25
B31: US Live births | G31: =G29*G30 -> 765 | H31: =H29*H30 -> 765 | I31: =I29*I30 -> 765 | J31: =J29*J30 -> 765 | K31: =K29*K30 -> 765 | L31: =L29*L30 -> 765 | M31: =M29*M30 -> 765 | N31: =N29*N30 -> 765 | ... X31: =X29*X30 -> 765
B32: Incidence /mn | C32: [1] | G32: 3.6 | H32: 3.6 | I32: 3.6 | J32: 3.6 | K32: 3.6 | L32: 3.6 | M32: 3.6 | N32: 3.6 | O32: 3.6 | P32: 3.6 | Q32: 3.6 | R32: 3.6 | S32: 3.6 | T32: 3.6 | U32: 3.6 | V32: 3.6 | W32: 3.6 | X32: 3.6
B33: Incidence total | G33: 5.55 | H33: 5.55 | I33: 5.55 | J33: 5.55 | K33: 5.55 | L33: 5.55 | M33: 5.55 | N33: 5.55 | O33: 5.55 | P33: 5.55 | Q33: 5.55 | R33: 5.55 | S33: 5.55 | T33: 5.55 | U33: 5.55 | V33: 5.55 | W33: 5.55 | X33: 5.55
B34: BOP treatment opportunities | C34: [3] | G34: =G33*G32 -> 19.98 | H34: =H33*H32 -> 19.98 | I34: =I33*I32 -> 19.98 | J34: =J33*J32 -> 19.98 | K34: =K33*K32 -> 19.98 | L34: =L33*L32 -> 19.98 | M34: =M33*M32 -> 19.98 | N34: =N33*N32 -> 19.98 | ... X34: =X33*X32 -> 19.98
B35: treatments administered | G35: =G31*0.8*2 -> 1224 | H35: =G35-G36+H34*2*0.8 -> 1230.968 | I35: =H35-H36+I34*2*0.8 -> 1152.936 | J35: =I35-I36+J34*2*0.8 -> 984.904 | K35: =J35-J36+K34*2*0.8 -> 816.872 | L35: =K35-K36+L34*2*0.8 -> 648.84 | M35: =L35-L36+M34*2*0.8 -> 480.808 | N35: =M35-M36+N34*2*0.8 -> 312.776 | O35: =N35-N36+O34*2*0.8 -> 144.744 | ... X35: =W35-W36+X34*2*0.8 -> 31.968 | Y35: =SUM(G36:X36) -> 1767.456
B36: Price per treatment | C36: [5] | G36: 25 | H36: 110 | I36: 200 | J36: 200 | K36: 200 | L36: 200 | M36: 200 | N36: 200 | O36: =O35 -> 144.744 | P36: =P35 -> 31.968 | Q36: =Q35 -> 31.968 | R36: =R35 -> 31.968 | S36: =S35 -> 31.968 | T36: =T35 -> 31.968 | U36: =U35 -> 31.968 | V36: =V35 -> 31.968 | ... X36: =X35 -> 31.968
B37: Price (ASP) | G37: 1500000 | H37: =G37*1.02 -> 1530000 | I37: =H37*1.02 -> 1560600 | J37: =I37*1.02 -> 1591812 | K37: =J37*1.02 -> 1623648.2 | L37: =K37*1.02 -> 1656121.2 | M37: =L37*1.02 -> 1689243.6 | N37: =M37*1.02 -> 1723028.5 | O37: =N37*1.02 -> 1757489.1 | ... X37: =W37*1.02 -> 2100362.1
B38: Revenue | G38: =G37*0.74 -> 1110000 | H38: =H37*0.74 -> 1132200 | I38: =I37*0.74 -> 1154844 | J38: =J37*0.74 -> 1177940.9 | K38: =K37*0.74 -> 1201499.7 | L38: =L37*0.74 -> 1225529.7 | M38: =M37*0.74 -> 1250040.3 | N38: =N37*0.74 -> 1275041.1 | ... X38: =X37*0.74 -> 1554268
B39: COGS | C39: [6] | G39: =G36*G38/1000000 -> 27.75 | H39: =H36*H38/1000000 -> 124.542 | I39: =I36*I38/1000000 -> 230.9688 | J39: =J36*J38/1000000 -> 235.58818 | K39: =K36*K38/1000000 -> 240.29994 | L39: =L36*L38/1000000 -> 245.10594 | M39: =M36*M38/1000000 -> 250.00806 | N39: =N36*N38/1000000 -> 255.00822 | ... X39: =X36*X38/1000000 -> 49.686839
B40: Gross profit | G40: =G39*0.15 -> 4.1625 | H40: =H39*0.15 -> 18.6813 | I40: =I39*0.15 -> 34.64532 | J40: =J39*0.15 -> 35.338226 | K40: =K39*0.15 -> 36.044991 | L40: =L39*0.15 -> 36.765891 | M40: =M39*0.15 -> 37.501209 | N40: =N39*0.15 -> 38.251233 | ... X40: =X39*0.15 -> 7.4530258
G41: =G39-G40 -> 23.5875 | H41: =H39-H40 -> 105.8607 | I41: =I39-I40 -> 196.32348 | J41: =J39-J40 -> 200.24995 | K41: =K39-K40 -> 204.25495 | L41: =L39-L40 -> 208.34005 | M41: =M39-M40 -> 212.50685 | N41: =N39-N40 -> 216.75699 | ... X41: =X39-X40 -> 42.233813
B42: R&D | D42: 28.97 | E42: 31.09 | F42: 34.36
B43: General & Administrative | D43: 17.26 | E43: 19 | F43: 29.85 | G43: 5 | H43: 5 | I43: 5 | J43: 5 | K43: 5 | L43: 5 | M43: 5 | N43: 5 | O43: 5 | P43: 5 | Q43: 5 | R43: 5 | S43: 5 | T43: 5 | U43: 5 | V43: 5 | W43: 5 | X43: 5
...

Sheet risk adjusted post approval 
A1: Research
B3: RDEB All | C3: Prevalence / mn | D3: Incidence /mn | E3: US pop mn | F3: Patient pop | G3: Notes
B4: Eichstadt et al (2019) | C4: =12562/340 -> 36.947059 | D4: 95 | E4: 340 | F4: =C4*E4 -> 12562 | G4: Unreliable genetic model
B5: Prop. Claims analysis (Abeona) | C5: =750/E5 -> 2.2058824 | D5: NA | E5: 340 | F5: 750 | G5: Method unavailable
A6: > | B6: Fine et al | C6: 1.35 | D6: 3.05 | E6: 340 | F6: =C6*E6 -> 459 | G6: NEBR data, most commonly cited
A7: > | B7: Baardman et al | C7: 2.1 | D7: 5.5 | E7: 340 | F7: =E7*C7 -> 714 | G7: Dutch EB registry
B8: Kim et al | E8: 340
A9: > | B9: Petrof et al | C9: 3.3 | D9: 8.1 | E9: 340 | F9: =C9*E9 -> 1122 | G9: NHS England and Wales
B10: Average | C10: =AVERAGE(C6:C9) -> 2.25 | D10: =AVERAGE(D6:D9) -> 5.55 | F10: =AVERAGE(F6:F9) -> 765
B12: RDEB patient "churn rate" | C12: =(D10*3.6)/F10 -> 0.026117647
B13: Implied life expectancy | C13: =1/C12 -> 38.288288
B14: Assuming 3.6 million live births
I15: (approval)
B16: Competition | C16: Vyjuvek | E16: KRYS valuation | H16: KRYS uptake | I16: Q2 2023 | J16: Q3 2023 | K16: Q4 2023 | L16: Q1 2024 | M16: Q2 2024 | N16: Q3 2024 | O16: Q4 2024
B17: Marketing auth holder | C17: KRYS | E17: MC | F17: =IFERROR(__xludf.DUMMYFUNCTION("googlefinance(""KRYS"",""marketcap"")/1000000"),3953.301208) -> 3953.3012 | G17: M | H17: Revenue | J17: 8.6 | K17: 42.1 | L17: 45.3 | M17: 70.3 | N17: 83.8 | O17: 91.1
B18: annualised sales (ASP) | C18: =91.1 * 4 -> 364.4 | E18: Cash | F18: 597.5 | G18: M | H18: Patients treated | J18: =J17*1000000/($F$21/4) -> 68.690967 | K18: =K17*1000000/($F$21/4) -> 336.26624 | L18: =L17*1000000/($F$21/4) -> 361.82567 | M18: =M17*1000000/($F$21/4) -> 561.50872 | N18: =N17*1000000/($F$21/4) -> 669.33756 | O18: =O17*1000000/($F$21/4) -> 727.64501
B19: Sales (retail) | C19: =C18*1.26 -> 459.144 | E19: EV | F19: =F17-F18 -> 3355.8012 | G19: M | H19: patient pop | J19: =$C$23 -> 1108.4 | K19: =$C$23 -> 1108.4 | L19: =$C$23 -> 1108.4 | M19: =$C$23 -> 1108.4 | N19: =$C$23 -> 1108.4 | O19: =$C$23 -> 1108.4
B20: Pricing (list) - patient year | C20: 631000 | E20: Peak sales | F20: =F21*F22/1000000 -> 628.27586 | G20: M | H20: % of peak | J20: =J18/J19 -> 0.061973084 | K20: =K18/K19 -> 0.30337987 | L20: =L18/L19 -> 0.32643962 | M20: =M18/M19 -> 0.50659393 | N20: =N18/N19 -> 0.60387726 | O20: =O18/O19 -> 0.65648232
B21: Patients | C21: =C19*1000000/C20 -> 727.64501 | E21: ASP/patient y | F21: =C18*1000000/C21 -> 500793.65 | G21: $ | O21: quick uptake
A22: 4y ramp | B22: Peak patients | C22: =C21/0.58 -> 1254.5604 | D22: RDEB + DDEB | E22: Peak patients | F22: =C22 -> 1254.5604
A23: sanity check | B23: DEB prevalence (JD Fine) | C23: =340*3.26 -> 1108.4 | E23: EV-Peak sales | F23: =F19/F20 -> 5.3412862 | G23: x
E24: EV-Sales | F24: =F19/C18 -> 9.2091142 | G24: x
A26: Model | B26: rNPV
Q27: check patent expiry date ...
C28: 2022 | D28: 2023 | E28: 2024 | F28: 2025 | G28: =F28+1 -> 2026 | H28: =G28+1 -> 2027 | I28: =H28+1 -> 2028 | J28: =I28+1 -> 2029 | K28: =J28+1 -> 2030 | L28: =K28+1 -> 2031 | M28: =L28+1 -> 2032 | N28: =M28+1 -> 2033 | ... W28: =V28+1 -> 2042
B29: US population | F29: 340 | G29: 340 | H29: 340 | I29: 340 | J29: 340 | K29: 340 | L29: 340 | M29: 340 | N29: 340 | O29: 340 | P29: 340 | Q29: 340 | R29: 340 | S29: 340 | T29: 340 | U29: 340 | V29: 340 | W29: 340
B30: Prevalence | F30: =AVERAGE($C$9,$C$7,$C$6) -> 2.25 | G30: =AVERAGE($C$9,$C$7,$C$6) -> 2.25 | H30: =AVERAGE($C$9,$C$7,$C$6) -> 2.25 | I30: =AVERAGE($C$9,$C$7,$C$6) -> 2.25 | J30: =AVERAGE($C$9,$C$7,$C$6) -> 2.25 | K30: =AVERAGE($C$9,$C$7,$C$6) -> 2.25 | L30: =AVERAGE($C$9,$C$7,$C$6) -> 2.25 | M30: =AVERAGE($C$9,$C$7,$C$6) -> 2.25 | ... W30: =AVERAGE($C$9,$C$7,$C$6) -> 2.25
B31: Patient population | F31: =F29*F30 -> 765 | G31: =G29*G30 -> 765 | H31: =H29*H30 -> 765 | I31: =I29*I30 -> 765 | J31: =J29*J30 -> 765 | K31: =K29*K30 -> 765 | L31: =L29*L30 -> 765 | M31: =M29*M30 -> 765 | ... W31: =W29*W30 -> 765
B32: US Live births | F32: 3.6 | G32: 3.6 | H32: 3.6 | I32: 3.6 | J32: 3.6 | K32: 3.6 | L32: 3.6 | M32: 3.6 | N32: 3.6 | O32: 3.6 | P32: 3.6 | Q32: 3.6 | R32: 3.6 | S32: 3.6 | T32: 3.6 | U32: 3.6 | V32: 3.6 | W32: 3.6
B33: Incidence /mn | F33: 5.55 | G33: 5.55 | H33: 5.55 | I33: 5.55 | J33: 5.55 | K33: 5.55 | L33: 5.55 | M33: 5.55 | N33: 5.55 | O33: 5.55 | P33: 5.55 | Q33: 5.55 | R33: 5.55 | S33: 5.55 | T33: 5.55 | U33: 5.55 | V33: 5.55 | W33: 5.55
B34: Incidence total | F34: =F33*F32 -> 19.98 | G34: =G33*G32 -> 19.98 | H34: =H33*H32 -> 19.98 | I34: =I33*I32 -> 19.98 | J34: =J33*J32 -> 19.98 | K34: =K33*K32 -> 19.98 | L34: =L33*L32 -> 19.98 | M34: =M33*M32 -> 19.98 | ... W34: =W33*W32 -> 19.98
B35: BOP treatment opportunities | F35: =F31*0.8 -> 612 | G35: =F35-F36+G34*0.8 -> 617.984 | H35: =G35-G36+H34*0.8 -> 583.968 | I35: =H35-H36+I34*0.8 -> 479.952 | J35: =I35-I36+J34*0.8 -> 375.936 | K35: =J35-J36+K34*0.8 -> 271.92 | L35: =K35-K36+L34*0.8 -> 15.984 | M35: =L35-L36+M34*0.8 -> 15.984 | N35: =M35-M36+N34*0.8 -> 15.984 | ... W35: =V35-V36+W34*0.8 -> 15.984
B36: treatments administered | F36: 10 | G36: 50 | H36: 120 | I36: 120 | J36: 120 | K36: =K35 -> 271.92 | L36: =L35 -> 15.984 | M36: =M35 -> 15.984 | N36: =N35 -> 15.984 | O36: =O35 -> 15.984 | P36: =P35 -> 15.984 | Q36: =Q35 -> 15.984 | R36: =R35 -> 15.984 | ... W36: =W35 -> 15.984
B37: Price per treatment | F37: 3100000 | G37: =F37*1.02 -> 3162000 | H37: =G37*1.02 -> 3225240 | I37: =H37*1.02 -> 3289744.8 | J37: =I37*1.02 -> 3355539.7 | K37: =J37*1.02 -> 3422650.5 | L37: =K37*1.02 -> 3491103.5 | M37: =L37*1.02 -> 3560925.6 | N37: =M37*1.02 -> 3632144.1 | ... W37: =V37*1.02 -> 4340748.4
B38: Price (ASP) | F38: =F37*0.74 -> 2294000 | G38: =G37*0.74 -> 2339880 | H38: =H37*0.74 -> 2386677.6 | I38: =I37*0.74 -> 2434411.2 | J38: =J37*0.74 -> 2483099.4 | K38: =K37*0.74 -> 2532761.4 | L38: =L37*0.74 -> 2583416.6 | M38: =M37*0.74 -> 2635084.9 | ... W38: =W37*0.74 -> 3212153.8
A39: =SUM(G39:W39) -> 2236.0349 | B39: Revenue | F39: =F36*F38/1000000 -> 22.94 | G39: =G36*G38/1000000 -> 116.994 | H39: =H36*H38/1000000 -> 286.40131 | I39: =I36*I38/1000000 -> 292.12934 | J39: =J36*J38/1000000 -> 297.97193 | K39: =K36*K38/1000000 -> 688.70847 | L39: =L36*L38/1000000 -> 41.293331 | M39: =M36*M38/1000000 -> 42.119197 | ... W39: =W36*W38/1000000 -> 51.343067
B40: COGS | F40: =F39*0.15 -> 3.441 | G40: =G39*0.15 -> 17.5491 | H40: =H39*0.15 -> 42.960197 | I40: =I39*0.15 -> 43.819401 | J40: =J39*0.15 -> 44.695789 | K40: =K39*0.15 -> 103.30627 | L40: =L39*0.15 -> 6.1939996 | M40: =M39*0.15 -> 6.3178796 | ... W40: =W39*0.15 -> 7.70146
B41: Gross profit | F41: =F39-F40 -> 19.499 | G41: =G39-G40 -> 99.4449 | H41: =H39-H40 -> 243.44112 | I41: =I39-I40 -> 248.30994 | J41: =J39-J40 -> 253.27614 | K41: =K39-K40 -> 585.4022 | L41: =L39-L40 -> 35.099331 | M41: =M39-M40 -> 35.801318 | ... W41: =W39-W40 -> 43.641607
B42: (risk adjusted gross profit) | F42: =F41*0.5*0.43 +F41*0.5 -> 13.941785 | G42: =G41*0.5*0.43 +G41*0.5 -> 71.103104 | H42: =H41*0.5*0.43 +H41*0.5 -> 174.0604 | I42: =I41*0.5*0.43 +I41*0.5 -> 177.54161 | J42: =J41*0.5*0.43 +J41*0.5 -> 181.09244 | K42: =K41*0.5*0.43 +K41*0.5 -> 418.56257 | L42: =L41*0.5*0.43 +L41*0.5 -> 25.096022 | M42: =M41*0.5*0.43 +M41*0.5 -> 25.597942 | ... W42: =W41*0.5*0.43 +W41*0.5 -> 31.203749
B44: R&D | C44: 28.97 | D44: 31.09 | E44: 34.36 | F44: 5 | G44: 5 | H44: 5 | I44: 5 | J44: 5 | K44: 5 | L44: 5 | M44: 5 | N44: 5 | O44: 5 | P44: 5 | Q44: 5 | R44: 5 | S44: 5 | T44: 5 | U44: 5 | V44: 5 | W44: 5
...
